fuzzy-error-logs.txt

Successes: 10
Errors: 20
Command:
bosh exec launch dipy_deterministic_tracking.json example_invocation.json -v /data/:/data/ -v ${PWD}:${PWD}

Frobenius distances between connectomes:
(0,  ): 9326.941031227763
(0, 1): 4686.088774233796
(0, 2): 3139.1478142961028
(0, 3): 3139.1267894113485
(0, 4): 3139.1267894113485
(0, 5): 3139.1478142961028
(0, 6): 4686.122064137894
(0, 7): 312.7187234560796
(0, 8): 3139.1478142961028
(0, 9): 312.68034795938166
(1,  ): 14002.301703648583
(1, 2): 7818.096123737543
(1, 3): 7818.078216544012
(1, 4): 7818.078216544012
(1, 5): 7818.096123737543
(1, 6): 4.0
(1, 7): 4706.00626858911
(1, 8): 7818.096123737543
(1, 9): 4705.987994034834
(2,  ): 6192.223994656524
(2, 3): 2.0
(2, 4): 2.0
(2, 5): 0.0
(2, 6): 7818.133472894921
(2, 7): 3118.5381190551448
(2, 8): 0.0
(2, 9): 3118.556076135236
(3,  ): 6192.244019739533
(3, 4): 0.0
(3, 5): 2.0
(3, 6): 7818.114542522385
(3, 7): 3118.5214445310457
(3, 8): 2.0
(3, 9): 3118.5381190551448
(4,  ): 6192.244019739533
(4, 5): 2.0
(4, 6): 7818.114542522385
(4, 7): 3118.5214445310457
(4, 8): 2.0
(4, 9): 3118.5381190551448
(5,  ): 6192.223994656524
(5, 6): 7818.133472894921
(5, 7): 3118.5381190551448
(5, 8): 0.0
(5, 9): 3118.556076135236
(6,  ): 14002.339983017124
(6, 7): 4706.0453673971315
(6, 8): 7818.133472894921
(6, 9): 4706.025393046663
(7,  ): 9302.224895152773
(7, 8): 3118.5381190551448
(7, 9): 2.0
(8,  ): 6192.223994656524
(8, 9): 3118.556076135236
(9,  ): 9302.244030340205

Unique errors:
Traceback (most recent call last):
  File "/opt/dipy_deterministic_tracking.py", line 234, in <module>
    main()
  File "/opt/dipy_deterministic_tracking.py", line 209, in main
    fibers, plot=results.streamline_plot)
  File "/opt/dipy_deterministic_tracking.py", line 77, in dwi_deterministic_tracing
    affine=np.eye(4), step_size=0.5)
  File "/usr/local/lib/python3.6/site-packages/dipy/tracking/local/localtracking.py", line 89, in __init__
    self._voxel_size = np.ascontiguousarray(self._get_voxel_size(affine),
  File "/usr/local/lib/python3.6/site-packages/dipy/tracking/local/localtracking.py", line 32, in _get_voxel_size
    if not np.allclose(np.triu(dotlin, 1), 0., atol=1e-5):
  File "<__array_function__ internals>", line 6, in triu
  File "/usr/local/lib/python3.6/site-packages/numpy/lib/twodim_base.py", line 467, in triu
    return where(mask, zeros(1, m.dtype), m)
  File "<__array_function__ internals>", line 6, in where
ValueError: operands could not be broadcast together with shapes (4,3) (1,) (3,3)

Traceback (most recent call last):
  File "/opt/dipy_deterministic_tracking.py", line 234, in <module>
    main()
  File "/opt/dipy_deterministic_tracking.py", line 209, in main
    fibers, plot=results.streamline_plot)
  File "/opt/dipy_deterministic_tracking.py", line 73, in dwi_deterministic_tracing
    affine=np.eye(4))
  File "/usr/local/lib/python3.6/site-packages/dipy/tracking/utils.py", line 390, in seeds_from_mask
    grid = np.mgrid[0:density[0], 0:density[1], 0:density[2]]
  File "/usr/local/lib/python3.6/site-packages/numpy/lib/index_tricks.py", line 173, in __getitem__
    nn = _nx.indices(size, typ)
  File "/usr/local/lib/python3.6/site-packages/numpy/core/numeric.py", line 1712, in indices
    shape[:i] + (dim,) + shape[i+1:]
ValueError: cannot reshape array of size 4 into shape (3,1,1)

Traceback (most recent call last):
  File "/opt/dipy_deterministic_tracking.py", line 234, in <module>
    main()
  File "/opt/dipy_deterministic_tracking.py", line 209, in main
    fibers, plot=results.streamline_plot)
  File "/opt/dipy_deterministic_tracking.py", line 77, in dwi_deterministic_tracing
    affine=np.eye(4), step_size=0.5)
  File "/usr/local/lib/python3.6/site-packages/dipy/tracking/local/localtracking.py", line 89, in __init__
    self._voxel_size = np.ascontiguousarray(self._get_voxel_size(affine),
  File "/usr/local/lib/python3.6/site-packages/dipy/tracking/local/localtracking.py", line 32, in _get_voxel_size
    if not np.allclose(np.triu(dotlin, 1), 0., atol=1e-5):
  File "<__array_function__ internals>", line 6, in triu
  File "/usr/local/lib/python3.6/site-packages/numpy/lib/twodim_base.py", line 467, in triu
    return where(mask, zeros(1, m.dtype), m)
  File "<__array_function__ internals>", line 6, in where
ValueError: operands could not be broadcast together with shapes (3,4) (1,) (3,3)

Traceback (most recent call last):
  File "/opt/dipy_deterministic_tracking.py", line 234, in <module>
    main()
  File "/opt/dipy_deterministic_tracking.py", line 209, in main
    fibers, plot=results.streamline_plot)
  File "/opt/dipy_deterministic_tracking.py", line 73, in dwi_deterministic_tracing
    affine=np.eye(4))
  File "/usr/local/lib/python3.6/site-packages/dipy/tracking/utils.py", line 390, in seeds_from_mask
    grid = np.mgrid[0:density[0], 0:density[1], 0:density[2]]
  File "/usr/local/lib/python3.6/site-packages/numpy/lib/index_tricks.py", line 173, in __getitem__
    nn = _nx.indices(size, typ)
  File "/usr/local/lib/python3.6/site-packages/numpy/core/numeric.py", line 1712, in indices
    shape[:i] + (dim,) + shape[i+1:]
ValueError: cannot reshape array of size 4 into shape (1,1,3)

Traceback (most recent call last):
  File "/opt/dipy_deterministic_tracking.py", line 234, in <module>
    main()
  File "/opt/dipy_deterministic_tracking.py", line 209, in main
    fibers, plot=results.streamline_plot)
  File "/opt/dipy_deterministic_tracking.py", line 73, in dwi_deterministic_tracing
    affine=np.eye(4))
  File "/usr/local/lib/python3.6/site-packages/dipy/tracking/utils.py", line 390, in seeds_from_mask
    grid = np.mgrid[0:density[0], 0:density[1], 0:density[2]]
  File "/usr/local/lib/python3.6/site-packages/numpy/lib/index_tricks.py", line 173, in __getitem__
    nn = _nx.indices(size, typ)
  File "/usr/local/lib/python3.6/site-packages/numpy/core/numeric.py", line 1712, in indices
    shape[:i] + (dim,) + shape[i+1:]
ValueError: cannot reshape array of size 4 into shape (1,3,1)

Traceback (most recent call last):
  File "/opt/dipy_deterministic_tracking.py", line 234, in <module>
    main()
  File "/opt/dipy_deterministic_tracking.py", line 209, in main
    fibers, plot=results.streamline_plot)
  File "/opt/dipy_deterministic_tracking.py", line 73, in dwi_deterministic_tracing
    affine=np.eye(4))
  File "/usr/local/lib/python3.6/site-packages/dipy/tracking/utils.py", line 390, in seeds_from_mask
    grid = np.mgrid[0:density[0], 0:density[1], 0:density[2]]
  File "/usr/local/lib/python3.6/site-packages/numpy/lib/index_tricks.py", line 173, in __getitem__
    nn = _nx.indices(size, typ)
  File "/usr/local/lib/python3.6/site-packages/numpy/core/numeric.py", line 1712, in indices
    shape[:i] + (dim,) + shape[i+1:]
ValueError: cannot reshape array of size 3 into shape (1,2,1)

Traceback (most recent call last):
  File "/opt/dipy_deterministic_tracking.py", line 234, in <module>
    main()
  File "/opt/dipy_deterministic_tracking.py", line 209, in main
    fibers, plot=results.streamline_plot)
  File "/opt/dipy_deterministic_tracking.py", line 78, in dwi_deterministic_tracing
    streamlines = Streamlines(streamlines_generator)
  File "/usr/local/lib/python3.6/site-packages/nibabel/streamlines/array_sequence.py", line 103, in __init__
    self.extend(iterable)
  File "/usr/local/lib/python3.6/site-packages/nibabel/streamlines/array_sequence.py", line 250, in extend
    for e in elements:
  File "/usr/local/lib/python3.6/site-packages/dipy/tracking/utils.py", line 957, in move_streamlines
    for sl in streamlines:
  File "/usr/local/lib/python3.6/site-packages/dipy/tracking/local/localtracking.py", line 131, in _generate_streamlines
    directions = self.direction_getter.initial_direction(s)
  File "dipy/reconst/peak_direction_getter.pyx", line 75, in dipy.reconst.peak_direction_getter.PeaksAndMetricsDirectionGetter.initial_direction
IndexError: point outside data

Traceback (most recent call last):
  File "/opt/dipy_deterministic_tracking.py", line 234, in <module>
    main()
  File "/opt/dipy_deterministic_tracking.py", line 209, in main
    fibers, plot=results.streamline_plot)
  File "/opt/dipy_deterministic_tracking.py", line 73, in dwi_deterministic_tracing
    affine=np.eye(4))
  File "/usr/local/lib/python3.6/site-packages/dipy/tracking/utils.py", line 390, in seeds_from_mask
    grid = np.mgrid[0:density[0], 0:density[1], 0:density[2]]
  File "/usr/local/lib/python3.6/site-packages/numpy/lib/index_tricks.py", line 173, in __getitem__
    nn = _nx.indices(size, typ)
  File "/usr/local/lib/python3.6/site-packages/numpy/core/numeric.py", line 1712, in indices
    shape[:i] + (dim,) + shape[i+1:]
ValueError: cannot reshape array of size 3 into shape (2,1,1)

Traceback (most recent call last):
  File "/opt/dipy_deterministic_tracking.py", line 234, in <module>
    main()
  File "/opt/dipy_deterministic_tracking.py", line 209, in main
    fibers, plot=results.streamline_plot)
  File "/opt/dipy_deterministic_tracking.py", line 73, in dwi_deterministic_tracing
    affine=np.eye(4))
  File "/usr/local/lib/python3.6/site-packages/dipy/tracking/utils.py", line 390, in seeds_from_mask
    grid = np.mgrid[0:density[0], 0:density[1], 0:density[2]]
  File "/usr/local/lib/python3.6/site-packages/numpy/lib/index_tricks.py", line 173, in __getitem__
    nn = _nx.indices(size, typ)
  File "/usr/local/lib/python3.6/site-packages/numpy/core/numeric.py", line 1712, in indices
    shape[:i] + (dim,) + shape[i+1:]
ValueError: cannot reshape array of size 3 into shape (1,1,2)